<?xml version="1.0" ?>
<!-- =================================================================================== -->
<!-- |    This document was autogenerated by xacro from /home/student/MiR100_2/src/MiR100_robolab/mirco_description/urdf/mirco.urdf.xacro | -->
<!-- |    EDITING THIS FILE BY HAND IS NOT RECOMMENDED                                 | -->
<!-- =================================================================================== -->
<robot name="mirco_robot">
    <!-- necessary because args cannot be accessed inside ${} expressions -->
    <link name="mir100_base_footprint" />
    <joint name="mir100_base_joint" type="fixed">
        <parent link="mir100_base_footprint" />
        <child link="mir100_base_link" />
        <origin rpy="0 0 0" xyz="0 0 0" />
    </joint>
    <link name="mir100_base_link">
        <inertial>
            <mass value="77.0" />
            <origin rpy="0 0 0" xyz="-0.012354000000000004 0.0 0.15" />
            <inertia ixx="0.8341663330000001" ixy="0.0" ixz="0.0" iyy="1.8608325890000004" iyz="0.0" izz="2.1816657939999997" />
        </inertial>
        <visual>
            <origin rpy="0 0 0" xyz="0.037646 0 0" />
            <geometry>
                <mesh filename="package://mir_description/meshes/visual/mir_100_base.stl" />
            </geometry>
            <material name="white">
                <color rgba="1 1 1 1" />
            </material>
        </visual>
        <collision>
            <origin rpy="0 0 0" xyz="0.037646 0 0" />
            <geometry>
                <mesh filename="package://mir_description/meshes/collision/mir_100_base.stl" />
            </geometry>
        </collision>
    </link>
    <gazebo reference="mir100_base_link">
        <material>Gazebo/White</material>
        <plugin name="gazebo_ros_control">
            <robotNamespace>/</robotNamespace>
        </plugin>
    </gazebo>
    <!-- IMU -->
    <joint name="mir100_base_link_to_imu_joint" type="fixed">
        <parent link="mir100_base_link" />
        <child link="mir100_imu_link" />
        <origin rpy="0 0 0" xyz="0.0 0.0 0.25" />
        <!-- same as real MiR -->
    </joint>
    <link name="mir100_imu_link" />
    <gazebo>
        <plugin filename="libhector_gazebo_ros_imu.so" name="imu_plugin">
            <updateRate>50.0</updateRate>
            <bodyName>mir100_imu_link</bodyName>
            <frameId>imu_frame</frameId>
            <!-- from real MiR -->
            <topicName>imu_data</topicName>
            <accelDrift>0.0 0.0 0.0</accelDrift>
            <accelGaussianNoise>0.007071067811865475 0.01 0.011401754250991379</accelGaussianNoise>
            <!-- real MiR linear_acceleration_covariance: [5e-05, 0.0, 0.0, 0.0, 0.0001, 0.0, 0.0, 0.0, 0.00013] -->
            <rateDrift>0.0 0.0 0.0</rateDrift>
            <rateGaussianNoise>0.00282842712474619 0.00282842712474619 0.0005477225575051661</rateGaussianNoise>
            <!-- real MiR angular_velocity_covariance: [8e-06, 0.0, 0.0, 0.0, 8e-06, 0.0, 0.0, 0.0, 3e-07] -->
            <yawDrift>0.0</yawDrift>
            <yawGaussianNoise>0.31622776601683794</yawGaussianNoise>
            <!-- real MiR orientation_covariance: [0.1, 0.0, 0.0, 0.0, 0.1, 0.0, 0.0, 0.0, 0.1] -->
        </plugin>
    </gazebo>
    <!-- Create an alias for imu_link. This is necessary because the real MiR's
         TF has imu_link, but the imu_data topic is published in the imu_frame
         frame. -->
    <joint name="mir100_imu_link_to_imu_frame_joint" type="fixed">
        <parent link="mir100_imu_link" />
        <child link="mir100_imu_frame" />
        <origin rpy="0 0 0" xyz="0 0 0" />
    </joint>
    <link name="mir100_imu_frame" />
    <!-- Laser scanners -->
    <joint name="mir100_base_link_to_front_laser_joint" type="fixed">
        <parent link="mir100_base_link" />
        <child link="mir100_front_laser_link" />
        <origin rpy="0.0 0.0 0.7853981633974483" xyz="0.42964600000000003 0.2358 0.1914" />
    </joint>
    <link name="mir100_front_laser_link">
        <visual>
            <origin rpy="3.141592653589793 0 0" xyz="0.0 0.0 0.0" />
            <geometry>
                <mesh filename="package://mir_description/meshes/visual/sick_lms-100.stl" />
            </geometry>
            <!-- <xacro:insert_block name="material_yellow" /> -->
            <material name="black">
                <color rgba="0.1 0.1 0.1 1" />
            </material>
        </visual>
        <collision>
            <origin rpy="3.141592653589793 0 0" xyz="0.0 0.0 0.0" />
            <geometry>
                <mesh filename="package://mir_description/meshes/visual/sick_lms-100.stl" />
            </geometry>
        </collision>
        <inertial>
            <mass value="1.2" />
            <origin xyz="0 0 0" rpy="0 0 0" />
            <inertia ixx="0.005824997669999999" ixy="0.0" ixz="0.0" iyy="0.00585609765756" iyz="0.0" izz="0.00483609806556" />
        </inertial>
    </link>
    <gazebo reference="mir100_front_laser_link">
        <!-- <material value="Gazebo/Yellow" /> -->
        <material value="Gazebo/FlatBlack" />
        <sensor name="mir100_front_laser_link" type="ray">
            <pose>0 0 0 0 0 0</pose>
            <visualize>false</visualize>
            <update_rate>12.5</update_rate>
            <ray>
                <scan>
                    <horizontal>
                        <samples>541</samples>
                        <resolution>1</resolution>
                        <!-- has to be 1; actual resolution will be computed from number of samples + min_angle/max_angle -->
                        <min_angle>-2.35619449615</min_angle>
                        <max_angle>2.35619449615</max_angle>
                    </horizontal>
                </scan>
                <range>
                    <min>0.05</min>
                    <max>29.0</max>
                    <resolution>0.01</resolution>
                </range>
                <noise>
                    <type>gaussian</type>
                    <!-- Noise parameters based on published spec for S300 achieving
                 "+-29mm" accuracy at range < 3m (~0.01 of the range) at
                 1 sigma. -->
                    <mean>0.0</mean>
                    <stddev>0.01</stddev>
                </noise>
            </ray>
            <plugin filename="libgazebo_ros_laser.so" name="gazebo_ros_front_laser_link_controller">
                <frameName>mir100_front_laser_link</frameName>
                <topicName>f_scan</topicName>
            </plugin>
        </sensor>
    </gazebo>
    <joint name="mir100_base_link_to_back_laser_joint" type="fixed">
        <parent link="mir100_base_link" />
        <child link="mir100_back_laser_link" />
        <origin rpy="0.0 0.0 -2.356194490192345" xyz="-0.354354 -0.2358 0.1914" />
    </joint>
    <link name="mir100_back_laser_link">
        <visual>
            <origin rpy="3.141592653589793 0 0" xyz="0.0 0.0 0.0" />
            <geometry>
                <mesh filename="package://mir_description/meshes/visual/sick_lms-100.stl" />
            </geometry>
            <!-- <xacro:insert_block name="material_yellow" /> -->
            <material name="black">
                <color rgba="0.1 0.1 0.1 1" />
            </material>
        </visual>
        <collision>
            <origin rpy="3.141592653589793 0 0" xyz="0.0 0.0 0.0" />
            <geometry>
                <mesh filename="package://mir_description/meshes/visual/sick_lms-100.stl" />
            </geometry>
        </collision>
        <inertial>
            <mass value="1.2" />
            <origin xyz="0 0 0" rpy="0 0 0" />
            <inertia ixx="0.005824997669999999" ixy="0.0" ixz="0.0" iyy="0.00585609765756" iyz="0.0" izz="0.00483609806556" />
        </inertial>
    </link>
    <gazebo reference="mir100_back_laser_link">
        <!-- <material value="Gazebo/Yellow" /> -->
        <material value="Gazebo/FlatBlack" />
        <sensor name="mir100_back_laser_link" type="ray">
            <pose>0 0 0 0 0 0</pose>
            <visualize>false</visualize>
            <update_rate>12.5</update_rate>
            <ray>
                <scan>
                    <horizontal>
                        <samples>541</samples>
                        <resolution>1</resolution>
                        <!-- has to be 1; actual resolution will be computed from number of samples + min_angle/max_angle -->
                        <min_angle>-2.35619449615</min_angle>
                        <max_angle>2.35619449615</max_angle>
                    </horizontal>
                </scan>
                <range>
                    <min>0.05</min>
                    <max>29.0</max>
                    <resolution>0.01</resolution>
                </range>
                <noise>
                    <type>gaussian</type>
                    <!-- Noise parameters based on published spec for S300 achieving
                 "+-29mm" accuracy at range < 3m (~0.01 of the range) at
                 1 sigma. -->
                    <mean>0.0</mean>
                    <stddev>0.01</stddev>
                </noise>
            </ray>
            <plugin filename="libgazebo_ros_laser.so" name="gazebo_ros_back_laser_link_controller">
                <frameName>mir100_back_laser_link</frameName>
                <topicName>b_scan</topicName>
            </plugin>
        </sensor>
    </gazebo>
    <!-- Ultrasound sensors -->
    <joint name="mir100_us_1_joint" type="fixed">
        <!-- right ultrasound -->
        <parent link="mir100_base_link" />
        <child link="mir100_us_1_frame" />
        <origin rpy="0 0 0" xyz="0.45 -0.12 0.16 " />
        <!-- from visually matching to the mesh of the MiR -->
    </joint>
    <link name="mir100_us_1_frame" />
    <joint name="mir100_us_2_joint" type="fixed">
        <!-- left ultrasound -->
        <parent link="mir100_base_link" />
        <child link="mir100_us_2_frame" />
        <origin rpy="0 0 0" xyz="0.45 0.12 0.16 " />
        <!-- from visually matching to the mesh of the MiR -->
    </joint>
    <link name="mir100_us_2_frame" />
    <joint name="mir100_left_wheel_joint" type="continuous">
        <origin rpy="0 0 0" xyz="0.0 0.222604 0.0625" />
        <parent link="mir100_base_link" />
        <child link="mir100_left_wheel_link" />
        <axis xyz="0 1 0" />
        <limit effort="100" velocity="20.0" />
    </joint>
    <link name="mir100_left_wheel_link">
        <inertial>
            <mass value="1.0" />
            <origin rpy="1.5707963267948966 0 0" xyz="0 0 0" />
            <inertia ixx="0.001061895408575" ixy="0.0" ixz="0.0" iyy="0.001061895408575" iyz="0.0" izz="0.001953125" />
        </inertial>
        <visual>
            <origin rpy="1.5707963267948966 0 0" xyz="0 0 0" />
            <geometry>
                <cylinder length="0.032" radius="0.0625" />
            </geometry>
            <material name="black">
                <color rgba="0.1 0.1 0.1 1" />
            </material>
        </visual>
        <collision>
            <origin rpy="1.5707963267948966 0 0" xyz="0 0 0" />
            <geometry>
                <cylinder length="0.032" radius="0.0625" />
            </geometry>
        </collision>
    </link>
    <gazebo reference="mir100_left_wheel_link">
        <material>Gazebo/FlatBlack</material>
    </gazebo>
    <joint name="mir100_right_wheel_joint" type="continuous">
        <origin rpy="0 0 0" xyz="0.0 -0.222604 0.0625" />
        <parent link="mir100_base_link" />
        <child link="mir100_right_wheel_link" />
        <axis xyz="0 1 0" />
        <limit effort="100" velocity="20.0" />
    </joint>
    <link name="mir100_right_wheel_link">
        <inertial>
            <mass value="1.0" />
            <origin rpy="1.5707963267948966 0 0" xyz="0 0 0" />
            <inertia ixx="0.001061895408575" ixy="0.0" ixz="0.0" iyy="0.001061895408575" iyz="0.0" izz="0.001953125" />
        </inertial>
        <visual>
            <origin rpy="1.5707963267948966 0 0" xyz="0 0 0" />
            <geometry>
                <cylinder length="0.032" radius="0.0625" />
            </geometry>
            <material name="black">
                <color rgba="0.1 0.1 0.1 1" />
            </material>
        </visual>
        <collision>
            <origin rpy="1.5707963267948966 0 0" xyz="0 0 0" />
            <geometry>
                <cylinder length="0.032" radius="0.0625" />
            </geometry>
        </collision>
    </link>
    <gazebo reference="mir100_right_wheel_link">
        <material>Gazebo/FlatBlack</material>
    </gazebo>
    <!-- caster hub -->
    <joint name="mir100_fl_caster_rotation_joint" type="continuous">
        <origin rpy="0 0 0" xyz="0.34134600000000004 0.203 0.1565" />
        <parent link="mir100_base_link" />
        <child link="mir100_fl_caster_rotation_link" />
        <axis xyz="0 0 1" />
        <dynamics damping="0.01" friction="0.0" />
    </joint>
    <link name="mir100_fl_caster_rotation_link">
        <inertial>
            <!-- <origin xyz="0 0 -0.042500000044" rpy="${0.5 * pi} ${24 * deg_to_rad} ${1.5 * pi}" /> -->
            <origin rpy="0.41887903200000004 0 1.5707963267948966 " xyz="0 0 -0.042500000044" />
            <mass value="0.3097539019" />
            <inertia ixx="0.0005844517978" ixy="0" ixz="0" iyy="0.00052872551237" iyz="0" izz="0.00017923555074" />
        </inertial>
        <visual>
            <origin rpy="0 0 0" xyz="0 0 0" />
            <geometry>
                <mesh filename="package://mir_description/meshes/visual/caster_wheel_base.stl" />
            </geometry>
            <material name="silver">
                <color rgba="0.79 0.82 0.93 1" />
            </material>
        </visual>
        <collision>
            <origin rpy="0 0 0" xyz="0 0 0" />
            <geometry>
                <mesh filename="package://mir_description/meshes/collision/caster_wheel_base.stl" />
            </geometry>
        </collision>
    </link>
    <gazebo reference="mir100_fl_caster_rotation_link">
        <material>Gazebo/Grey</material>
    </gazebo>
    <!-- caster wheel -->
    <joint name="mir100_fl_caster_wheel_joint" type="continuous">
        <origin rpy="0 0 0" xyz="-0.0382 0 -0.094" />
        <parent link="mir100_fl_caster_rotation_link" />
        <child link="mir100_fl_caster_wheel_link" />
        <axis xyz="0 1 0" />
    </joint>
    <link name="mir100_fl_caster_wheel_link">
        <inertial>
            <mass value="1.0" />
            <origin rpy="1.5707963267948966 0 0" xyz="0 0 0" />
            <inertia ixx="0.001061895408575" ixy="0.0" ixz="0.0" iyy="0.001061895408575" iyz="0.0" izz="0.001953125" />
        </inertial>
        <visual>
            <origin rpy="1.5707963267948966 0 0" xyz="0 0 0" />
            <geometry>
                <cylinder length="0.032" radius="0.0625" />
            </geometry>
            <material name="black">
                <color rgba="0.1 0.1 0.1 1" />
            </material>
        </visual>
        <collision>
            <origin rpy="1.5707963267948966 0 0" xyz="0 0 0" />
            <geometry>
                <cylinder length="0.032" radius="0.0625" />
            </geometry>
        </collision>
    </link>
    <gazebo reference="mir100_fl_caster_wheel_link">
        <material>Gazebo/FlatBlack</material>
    </gazebo>
    <!-- caster hub -->
    <joint name="mir100_fr_caster_rotation_joint" type="continuous">
        <origin rpy="0 0 0" xyz="0.34134600000000004 -0.203 0.1565" />
        <parent link="mir100_base_link" />
        <child link="mir100_fr_caster_rotation_link" />
        <axis xyz="0 0 1" />
        <dynamics damping="0.01" friction="0.0" />
    </joint>
    <link name="mir100_fr_caster_rotation_link">
        <inertial>
            <!-- <origin xyz="0 0 -0.042500000044" rpy="${0.5 * pi} ${24 * deg_to_rad} ${1.5 * pi}" /> -->
            <origin rpy="0.41887903200000004 0 1.5707963267948966 " xyz="0 0 -0.042500000044" />
            <mass value="0.3097539019" />
            <inertia ixx="0.0005844517978" ixy="0" ixz="0" iyy="0.00052872551237" iyz="0" izz="0.00017923555074" />
        </inertial>
        <visual>
            <origin rpy="0 0 0" xyz="0 0 0" />
            <geometry>
                <mesh filename="package://mir_description/meshes/visual/caster_wheel_base.stl" />
            </geometry>
            <material name="silver">
                <color rgba="0.79 0.82 0.93 1" />
            </material>
        </visual>
        <collision>
            <origin rpy="0 0 0" xyz="0 0 0" />
            <geometry>
                <mesh filename="package://mir_description/meshes/collision/caster_wheel_base.stl" />
            </geometry>
        </collision>
    </link>
    <gazebo reference="mir100_fr_caster_rotation_link">
        <material>Gazebo/Grey</material>
    </gazebo>
    <!-- caster wheel -->
    <joint name="mir100_fr_caster_wheel_joint" type="continuous">
        <origin rpy="0 0 0" xyz="-0.0382 0 -0.094" />
        <parent link="mir100_fr_caster_rotation_link" />
        <child link="mir100_fr_caster_wheel_link" />
        <axis xyz="0 1 0" />
    </joint>
    <link name="mir100_fr_caster_wheel_link">
        <inertial>
            <mass value="1.0" />
            <origin rpy="1.5707963267948966 0 0" xyz="0 0 0" />
            <inertia ixx="0.001061895408575" ixy="0.0" ixz="0.0" iyy="0.001061895408575" iyz="0.0" izz="0.001953125" />
        </inertial>
        <visual>
            <origin rpy="1.5707963267948966 0 0" xyz="0 0 0" />
            <geometry>
                <cylinder length="0.032" radius="0.0625" />
            </geometry>
            <material name="black">
                <color rgba="0.1 0.1 0.1 1" />
            </material>
        </visual>
        <collision>
            <origin rpy="1.5707963267948966 0 0" xyz="0 0 0" />
            <geometry>
                <cylinder length="0.032" radius="0.0625" />
            </geometry>
        </collision>
    </link>
    <gazebo reference="mir100_fr_caster_wheel_link">
        <material>Gazebo/FlatBlack</material>
    </gazebo>
    <!-- caster hub -->
    <joint name="mir100_bl_caster_rotation_joint" type="continuous">
        <origin rpy="0 0 0" xyz="-0.270154 0.203 0.1565" />
        <parent link="mir100_base_link" />
        <child link="mir100_bl_caster_rotation_link" />
        <axis xyz="0 0 1" />
        <dynamics damping="0.01" friction="0.0" />
    </joint>
    <link name="mir100_bl_caster_rotation_link">
        <inertial>
            <!-- <origin xyz="0 0 -0.042500000044" rpy="${0.5 * pi} ${24 * deg_to_rad} ${1.5 * pi}" /> -->
            <origin rpy="0.41887903200000004 0 1.5707963267948966 " xyz="0 0 -0.042500000044" />
            <mass value="0.3097539019" />
            <inertia ixx="0.0005844517978" ixy="0" ixz="0" iyy="0.00052872551237" iyz="0" izz="0.00017923555074" />
        </inertial>
        <visual>
            <origin rpy="0 0 0" xyz="0 0 0" />
            <geometry>
                <mesh filename="package://mir_description/meshes/visual/caster_wheel_base.stl" />
            </geometry>
            <material name="silver">
                <color rgba="0.79 0.82 0.93 1" />
            </material>
        </visual>
        <collision>
            <origin rpy="0 0 0" xyz="0 0 0" />
            <geometry>
                <mesh filename="package://mir_description/meshes/collision/caster_wheel_base.stl" />
            </geometry>
        </collision>
    </link>
    <gazebo reference="mir100_bl_caster_rotation_link">
        <material>Gazebo/Grey</material>
    </gazebo>
    <!-- caster wheel -->
    <joint name="mir100_bl_caster_wheel_joint" type="continuous">
        <origin rpy="0 0 0" xyz="-0.0382 0 -0.094" />
        <parent link="mir100_bl_caster_rotation_link" />
        <child link="mir100_bl_caster_wheel_link" />
        <axis xyz="0 1 0" />
    </joint>
    <link name="mir100_bl_caster_wheel_link">
        <inertial>
            <mass value="1.0" />
            <origin rpy="1.5707963267948966 0 0" xyz="0 0 0" />
            <inertia ixx="0.001061895408575" ixy="0.0" ixz="0.0" iyy="0.001061895408575" iyz="0.0" izz="0.001953125" />
        </inertial>
        <visual>
            <origin rpy="1.5707963267948966 0 0" xyz="0 0 0" />
            <geometry>
                <cylinder length="0.032" radius="0.0625" />
            </geometry>
            <material name="black">
                <color rgba="0.1 0.1 0.1 1" />
            </material>
        </visual>
        <collision>
            <origin rpy="1.5707963267948966 0 0" xyz="0 0 0" />
            <geometry>
                <cylinder length="0.032" radius="0.0625" />
            </geometry>
        </collision>
    </link>
    <gazebo reference="mir100_bl_caster_wheel_link">
        <material>Gazebo/FlatBlack</material>
    </gazebo>
    <!-- caster hub -->
    <joint name="mir100_br_caster_rotation_joint" type="continuous">
        <origin rpy="0 0 0" xyz="-0.270154 -0.203 0.1565" />
        <parent link="mir100_base_link" />
        <child link="mir100_br_caster_rotation_link" />
        <axis xyz="0 0 1" />
        <dynamics damping="0.01" friction="0.0" />
    </joint>
    <link name="mir100_br_caster_rotation_link">
        <inertial>
            <!-- <origin xyz="0 0 -0.042500000044" rpy="${0.5 * pi} ${24 * deg_to_rad} ${1.5 * pi}" /> -->
            <origin rpy="0.41887903200000004 0 1.5707963267948966 " xyz="0 0 -0.042500000044" />
            <mass value="0.3097539019" />
            <inertia ixx="0.0005844517978" ixy="0" ixz="0" iyy="0.00052872551237" iyz="0" izz="0.00017923555074" />
        </inertial>
        <visual>
            <origin rpy="0 0 0" xyz="0 0 0" />
            <geometry>
                <mesh filename="package://mir_description/meshes/visual/caster_wheel_base.stl" />
            </geometry>
            <material name="silver">
                <color rgba="0.79 0.82 0.93 1" />
            </material>
        </visual>
        <collision>
            <origin rpy="0 0 0" xyz="0 0 0" />
            <geometry>
                <mesh filename="package://mir_description/meshes/collision/caster_wheel_base.stl" />
            </geometry>
        </collision>
    </link>
    <gazebo reference="mir100_br_caster_rotation_link">
        <material>Gazebo/Grey</material>
    </gazebo>
    <!-- caster wheel -->
    <joint name="mir100_br_caster_wheel_joint" type="continuous">
        <origin rpy="0 0 0" xyz="-0.0382 0 -0.094" />
        <parent link="mir100_br_caster_rotation_link" />
        <child link="mir100_br_caster_wheel_link" />
        <axis xyz="0 1 0" />
    </joint>
    <link name="mir100_br_caster_wheel_link">
        <inertial>
            <mass value="1.0" />
            <origin rpy="1.5707963267948966 0 0" xyz="0 0 0" />
            <inertia ixx="0.001061895408575" ixy="0.0" ixz="0.0" iyy="0.001061895408575" iyz="0.0" izz="0.001953125" />
        </inertial>
        <visual>
            <origin rpy="1.5707963267948966 0 0" xyz="0 0 0" />
            <geometry>
                <cylinder length="0.032" radius="0.0625" />
            </geometry>
            <material name="black">
                <color rgba="0.1 0.1 0.1 1" />
            </material>
        </visual>
        <collision>
            <origin rpy="1.5707963267948966 0 0" xyz="0 0 0" />
            <geometry>
                <cylinder length="0.032" radius="0.0625" />
            </geometry>
        </collision>
    </link>
    <gazebo reference="mir100_br_caster_wheel_link">
        <material>Gazebo/FlatBlack</material>
    </gazebo>
    <joint name="mir100_base_link_surface_joint" type="fixed">
        <origin rpy="0 0 0" xyz="0.037646 0 0.352" />
        <parent link="mir100_base_link" />
        <child link="mir100_surface" />
        <axis xyz="0 0 1" />
    </joint>
    <link name="mir100_surface" />
    <transmission name="mir100_left_wheel_trans">
        <type>transmission_interface/SimpleTransmission</type>
        <joint name="mir100_left_wheel_joint">
            <hardwareInterface>hardware_interface/VelocityJointInterface</hardwareInterface>
        </joint>
        <actuator name="mir100_left_wheel_motor">
            <hardwareInterface>hardware_interface/VelocityJointInterface</hardwareInterface>
            <mechanicalReduction>1</mechanicalReduction>
        </actuator>
    </transmission>
    <transmission name="mir100_right_wheel_trans">
        <type>transmission_interface/SimpleTransmission</type>
        <joint name="mir100_right_wheel_joint">
            <hardwareInterface>hardware_interface/VelocityJointInterface</hardwareInterface>
        </joint>
        <actuator name="mir100_right_wheel_motor">
            <hardwareInterface>hardware_interface/VelocityJointInterface</hardwareInterface>
            <mechanicalReduction>1</mechanicalReduction>
        </actuator>
    </transmission>
    <gazebo reference="mir100_left_wheel_link">
        <mu1 value="200" />
        <mu2 value="200" />
        <kp value="10000000.0" />
        <kd value="1.0" />
        <minDepth>0.01</minDepth>
    </gazebo>
    <gazebo reference="mir100_right_wheel_link">
        <mu1 value="200" />
        <mu2 value="200" />
        <kp value="10000000.0" />
        <kd value="1.0" />
        <minDepth>0.01</minDepth>
    </gazebo>
    <gazebo reference="mir100_fl_caster_wheel_link">
        <mu1 value="1" />
        <mu2 value="1" />
        <kp value="10000000.0" />
        <kd value="1.0" />
        <minDepth>0.01</minDepth>
    </gazebo>
    <gazebo reference="mir100_fr_caster_wheel_link">
        <mu1 value="1" />
        <mu2 value="1" />
        <kp value="10000000.0" />
        <kd value="1.0" />
        <minDepth>0.01</minDepth>
    </gazebo>
    <gazebo reference="mir100_bl_caster_wheel_link">
        <mu1 value="1" />
        <mu2 value="1" />
        <kp value="10000000.0" />
        <kd value="1.0" />
        <minDepth>0.01</minDepth>
    </gazebo>
    <gazebo reference="mir100_br_caster_wheel_link">
        <mu1 value="1" />
        <mu2 value="1" />
        <kp value="10000000.0" />
        <kd value="1.0" />
        <minDepth>0.01</minDepth>
    </gazebo>
    <gazebo>
        <plugin filename="libgazebo_ros_p3d.so" name="p3d_base_controller">
            <alwaysOn>true</alwaysOn>
            <updateRate>50.0</updateRate>
            <bodyName>mir100_base_footprint</bodyName>
            <topicName>base_pose_ground_truth</topicName>
            <gaussianNoise>0.01</gaussianNoise>
            <frameName>map</frameName>
            <xyzOffsets>0 0 0</xyzOffsets>
            <rpyOffsets>0 0 0</rpyOffsets>
        </plugin>
    </gazebo>
    <gazebo>
        <plugin filename="libgazebo_ros_control.so" name="gazebo_ros_control">
            <controlPeriod>0.001</controlPeriod>
            <legacyModeNS>false</legacyModeNS>
        </plugin>
    </gazebo>
    <!-- instead of the controller_plugin_gazebo, you can use the diffdrive controller like this: -->
    <!-- <xacro:diff_controller_plugin_gazebo prefix=""
      left_wheel_joint="left_wheel_joint"
      right_wheel_joint="right_wheel_joint"
      wheel_separation="${2*mir_act_wheel_dy}"
      wheel_radius="${mir_act_wheel_radius}"/>  
    -->
    <!-- ////////// battery and controller enclosure ////////// -->
    <joint name="mir_to_enclosure" type="fixed">
        <parent link="mir100_surface" />
        <child link="enclosure" />
        <origin rpy="0 0 0" xyz="0 0 0" />
    </joint>
    <link name="enclosure">
        <visual>
            <origin rpy="0 0 0" xyz="0 0 0.21" />
            <geometry>
                <box size="0.75 0.45 0.42" />
            </geometry>
            <material name="grey">
                <color rgba="0.69 0.69 0.69 1" />
            </material>
        </visual>
        <collision>
            <origin rpy="0 0 0" xyz="0 0 0.21" />
            <geometry>
                <box size="0.75 0.45 0.42" />
            </geometry>
        </collision>
        <inertial>
            <mass value="0.1" />
            <origin xyz="0 0 0" rpy="0 0 0" />
            <inertia ixx="0.03" iyy="0.03" izz="0.03" ixy="0.0" ixz="0.0" iyz="0.0" />
        </inertial>
    </link>
    <!--
    Base UR robot series xacro macro.

    NOTE: this is NOT a URDF. It cannot directly be loaded by consumers
    expecting a flattened '.urdf' file. See the top-level '.xacro' for that
    (but note: that .xacro must still be processed by the xacro command).

    For use in '.launch' files: use one of the 'load_urX.launch' convenience
    launch files.

    This file models the base kinematic chain of a UR robot, which then gets
    parameterised by various configuration files to convert it into a UR3(e),
    UR5(e), UR10(e), UR16e or UR20.

    NOTE: the default kinematic parameters (ie: link lengths, frame locations,
    offets, etc) do not correspond to any particular robot. They are defaults
    only. There WILL be non-zero offsets between the Forward Kinematics results
    in TF (ie: robot_state_publisher) and the values reported by the Teach
    Pendant.

    For accurate (and robot-specific) transforms, the 'kinematics_parameters_file'
    parameter MUST point to a .yaml file containing the appropriate values for
    the targetted robot.

    If using the UniversalRobots/Universal_Robots_ROS_Driver, follow the steps
    described in the readme of that repository to extract the kinematic
    calibration from the controller and generate the required .yaml file.

    Main author of the migration to yaml configs: Ludovic Delval.

    Contributors to previous versions (in no particular order):

     - Felix Messmer
     - Kelsey Hawkins
     - Wim Meeussen
     - Shaun Edwards
     - Nadia Hammoudeh Garcia
     - Dave Hershberger
     - G. vd. Hoorn
     - Philip Long
     - Dave Coleman
     - Miguel Prada
     - Mathias Luedtke
     - Marcel Schnirring
     - Felix von Drigalski
     - Felix Exner
     - Jimmy Da Silva
     - Ajit Krisshna N L
     - Muhammad Asif Rana
  -->
    <!--
    NOTE: the macro defined in this file is NOT part of the public API of this
          package. Users CANNOT rely on this file being available, or stored in
          this location. Nor can they rely on the existence of the macro.
  -->
    <transmission name="ur5e_shoulder_pan_trans">
        <type>transmission_interface/SimpleTransmission</type>
        <joint name="ur5e_shoulder_pan_joint">
            <hardwareInterface>hardware_interface/PositionJointInterface</hardwareInterface>
        </joint>
        <actuator name="ur5e_shoulder_pan_motor">
            <mechanicalReduction>1</mechanicalReduction>
            <hardwareInterface>hardware_interface/EffortJointInterface</hardwareInterface>
        </actuator>
    </transmission>
    <transmission name="ur5e_shoulder_lift_trans">
        <type>transmission_interface/SimpleTransmission</type>
        <joint name="ur5e_shoulder_lift_joint">
            <hardwareInterface>hardware_interface/PositionJointInterface</hardwareInterface>
        </joint>
        <actuator name="ur5e_shoulder_lift_motor">
            <mechanicalReduction>1</mechanicalReduction>
            <hardwareInterface>hardware_interface/EffortJointInterface</hardwareInterface>
        </actuator>
    </transmission>
    <transmission name="ur5e_elbow_trans">
        <type>transmission_interface/SimpleTransmission</type>
        <joint name="ur5e_elbow_joint">
            <hardwareInterface>hardware_interface/PositionJointInterface</hardwareInterface>
        </joint>
        <actuator name="ur5e_elbow_motor">
            <mechanicalReduction>1</mechanicalReduction>
            <hardwareInterface>hardware_interface/EffortJointInterface</hardwareInterface>
        </actuator>
    </transmission>
    <transmission name="ur5e_wrist_1_trans">
        <type>transmission_interface/SimpleTransmission</type>
        <joint name="ur5e_wrist_1_joint">
            <hardwareInterface>hardware_interface/PositionJointInterface</hardwareInterface>
        </joint>
        <actuator name="ur5e_wrist_1_motor">
            <mechanicalReduction>1</mechanicalReduction>
            <hardwareInterface>hardware_interface/EffortJointInterface</hardwareInterface>
        </actuator>
    </transmission>
    <transmission name="ur5e_wrist_2_trans">
        <type>transmission_interface/SimpleTransmission</type>
        <joint name="ur5e_wrist_2_joint">
            <hardwareInterface>hardware_interface/PositionJointInterface</hardwareInterface>
        </joint>
        <actuator name="ur5e_wrist_2_motor">
            <mechanicalReduction>1</mechanicalReduction>
            <hardwareInterface>hardware_interface/EffortJointInterface</hardwareInterface>
        </actuator>
    </transmission>
    <transmission name="ur5e_wrist_3_trans">
        <type>transmission_interface/SimpleTransmission</type>
        <joint name="ur5e_wrist_3_joint">
            <hardwareInterface>hardware_interface/PositionJointInterface</hardwareInterface>
        </joint>
        <actuator name="ur5e_wrist_3_motor">
            <mechanicalReduction>1</mechanicalReduction>
            <hardwareInterface>hardware_interface/EffortJointInterface</hardwareInterface>
        </actuator>
    </transmission>
    <!-- links: main serial chain -->
    <link name="ur5e_base_link" />
    <link name="ur5e_base_link_inertia">
        <visual>
            <origin rpy="0 0 3.141592653589793" xyz="0 0 0" />
            <geometry>
                <mesh filename="package://ur_description/meshes/ur5e/visual/base.dae" />
            </geometry>
            <material name="LightGrey">
                <color rgba="0.7 0.7 0.7 1.0" />
            </material>
        </visual>
        <collision>
            <origin rpy="0 0 3.141592653589793" xyz="0 0 0" />
            <geometry>
                <mesh filename="package://ur_description/meshes/ur5e/collision/base.stl" />
            </geometry>
        </collision>
        <inertial>
            <mass value="4.0" />
            <origin rpy="0 0 0" xyz="0 0 0" />
            <inertia ixx="0.00443333156" ixy="0.0" ixz="0.0" iyy="0.00443333156" iyz="0.0" izz="0.0072" />
        </inertial>
    </link>
    <link name="ur5e_shoulder_link">
        <visual>
            <origin rpy="0 0 3.141592653589793" xyz="0 0 0" />
            <geometry>
                <mesh filename="package://ur_description/meshes/ur5e/visual/shoulder.dae" />
            </geometry>
            <material name="LightGrey">
                <color rgba="0.7 0.7 0.7 1.0" />
            </material>
        </visual>
        <collision>
            <origin rpy="0 0 3.141592653589793" xyz="0 0 0" />
            <geometry>
                <mesh filename="package://ur_description/meshes/ur5e/collision/shoulder.stl" />
            </geometry>
        </collision>
        <inertial>
            <mass value="3.7" />
            <origin rpy="0 0 0" xyz="0 0 0" />
            <inertia ixx="0.010267495893" ixy="0.0" ixz="0.0" iyy="0.010267495893" iyz="0.0" izz="0.00666" />
        </inertial>
    </link>
    <link name="ur5e_upper_arm_link">
        <visual>
            <origin rpy="1.5707963267948966 0 -1.5707963267948966" xyz="0 0 0.138" />
            <geometry>
                <mesh filename="package://ur_description/meshes/ur5e/visual/upperarm.dae" />
            </geometry>
            <material name="LightGrey">
                <color rgba="0.7 0.7 0.7 1.0" />
            </material>
        </visual>
        <collision>
            <origin rpy="1.5707963267948966 0 -1.5707963267948966" xyz="0 0 0.138" />
            <geometry>
                <mesh filename="package://ur_description/meshes/ur5e/collision/upperarm.stl" />
            </geometry>
        </collision>
        <inertial>
            <mass value="8.393" />
            <origin rpy="0 1.5707963267948966 0" xyz="-0.2125 0.0 0.138" />
            <inertia ixx="0.1338857818623325" ixy="0.0" ixz="0.0" iyy="0.1338857818623325" iyz="0.0" izz="0.0151074" />
        </inertial>
    </link>
    <link name="ur5e_forearm_link">
        <visual>
            <origin rpy="1.5707963267948966 0 -1.5707963267948966" xyz="0 0 0.007" />
            <geometry>
                <mesh filename="package://ur_description/meshes/ur5e/visual/forearm.dae" />
            </geometry>
            <material name="LightGrey">
                <color rgba="0.7 0.7 0.7 1.0" />
            </material>
        </visual>
        <collision>
            <origin rpy="1.5707963267948966 0 -1.5707963267948966" xyz="0 0 0.007" />
            <geometry>
                <mesh filename="package://ur_description/meshes/ur5e/collision/forearm.stl" />
            </geometry>
        </collision>
        <inertial>
            <mass value="2.275" />
            <origin rpy="0 1.5707963267948966 0" xyz="-0.1961 0.0 0.007" />
            <inertia ixx="0.031209355099586295" ixy="0.0" ixz="0.0" iyy="0.031209355099586295" iyz="0.0" izz="0.004095" />
        </inertial>
    </link>
    <link name="ur5e_wrist_1_link">
        <visual>
            <!-- TODO: Move this to a parameter -->
            <origin rpy="1.5707963267948966 0 0" xyz="0 0 -0.127" />
            <geometry>
                <mesh filename="package://ur_description/meshes/ur5e/visual/wrist1.dae" />
            </geometry>
            <material name="LightGrey">
                <color rgba="0.7 0.7 0.7 1.0" />
            </material>
        </visual>
        <collision>
            <origin rpy="1.5707963267948966 0 0" xyz="0 0 -0.127" />
            <geometry>
                <mesh filename="package://ur_description/meshes/ur5e/collision/wrist1.stl" />
            </geometry>
        </collision>
        <inertial>
            <mass value="1.219" />
            <origin rpy="0 0 0" xyz="0 0 0" />
            <inertia ixx="0.0025598989760400002" ixy="0.0" ixz="0.0" iyy="0.0025598989760400002" iyz="0.0" izz="0.0021942" />
        </inertial>
    </link>
    <link name="ur5e_wrist_2_link">
        <visual>
            <origin rpy="0 0 0" xyz="0 0 -0.0997" />
            <geometry>
                <mesh filename="package://ur_description/meshes/ur5e/visual/wrist2.dae" />
            </geometry>
            <material name="LightGrey">
                <color rgba="0.7 0.7 0.7 1.0" />
            </material>
        </visual>
        <collision>
            <origin rpy="0 0 0" xyz="0 0 -0.0997" />
            <geometry>
                <mesh filename="package://ur_description/meshes/ur5e/collision/wrist2.stl" />
            </geometry>
        </collision>
        <inertial>
            <mass value="1.219" />
            <origin rpy="0 0 0" xyz="0 0 0" />
            <inertia ixx="0.0025598989760400002" ixy="0.0" ixz="0.0" iyy="0.0025598989760400002" iyz="0.0" izz="0.0021942" />
        </inertial>
    </link>
    <link name="ur5e_wrist_3_link">
        <visual>
            <origin rpy="1.5707963267948966 0 0" xyz="0 0 -0.0989" />
            <geometry>
                <mesh filename="package://ur_description/meshes/ur5e/visual/wrist3.dae" />
            </geometry>
            <material name="LightGrey">
                <color rgba="0.7 0.7 0.7 1.0" />
            </material>
        </visual>
        <collision>
            <origin rpy="1.5707963267948966 0 0" xyz="0 0 -0.0989" />
            <geometry>
                <mesh filename="package://ur_description/meshes/ur5e/collision/wrist3.stl" />
            </geometry>
        </collision>
        <inertial>
            <mass value="0.1879" />
            <origin rpy="0 0 0" xyz="0.0 0.0 -0.0229" />
            <inertia ixx="9.890410052167731e-05" ixy="0.0" ixz="0.0" iyy="9.890410052167731e-05" iyz="0.0" izz="0.0001321171875" />
        </inertial>
    </link>
    <!-- joints: main serial chain -->
    <joint name="ur5e_base_link-base_link_inertia" type="fixed">
        <parent link="ur5e_base_link" />
        <child link="ur5e_base_link_inertia" />
        <!-- 'base_link' is REP-103 aligned (so X+ forward), while the internal
           frames of the robot/controller have X+ pointing backwards.
           Use the joint between 'base_link' and 'base_link_inertia' (a dummy
           link/frame) to introduce the necessary rotation over Z (of pi rad).
      -->
        <origin rpy="0 0 3.141592653589793" xyz="0 0 0" />
    </joint>
    <joint name="ur5e_shoulder_pan_joint" type="revolute">
        <parent link="ur5e_base_link_inertia" />
        <child link="ur5e_shoulder_link" />
        <origin rpy="0 0 -1.190729102401589e-07" xyz="0 0 0.1625558033973595" />
        <axis xyz="0 0 1" />
        <limit effort="150.0" lower="-6.283185307179586" upper="6.283185307179586" velocity="3.141592653589793" />
        <dynamics damping="0" friction="0" />
    </joint>
    <joint name="ur5e_shoulder_lift_joint" type="revolute">
        <parent link="ur5e_shoulder_link" />
        <child link="ur5e_upper_arm_link" />
        <origin rpy="1.570983101984359 0 2.586446182110655e-06" xyz="0.0001767646320481949 0 0" />
        <axis xyz="0 0 1" />
        <limit effort="150.0" lower="-6.283185307179586" upper="6.283185307179586" velocity="3.141592653589793" />
        <dynamics damping="0" friction="0" />
    </joint>
    <joint name="ur5e_elbow_joint" type="revolute">
        <parent link="ur5e_upper_arm_link" />
        <child link="ur5e_forearm_link" />
        <origin rpy="0.002042787025750159 -0.0006383341167318901 9.13069944119531e-06" xyz="-0.4252211792428467 0 0" />
        <axis xyz="0 0 1" />
        <limit effort="150.0" lower="-3.141592653589793" upper="3.141592653589793" velocity="3.141592653589793" />
        <dynamics damping="0" friction="0" />
    </joint>
    <joint name="ur5e_wrist_1_joint" type="revolute">
        <parent link="ur5e_forearm_link" />
        <child link="ur5e_wrist_1_link" />
        <origin rpy="0.003953248280165734 -0.00174058584206966 -1.133909506486874e-06" xyz="-0.3928185808484981 -0.0005259431618576967 0.1330400685052345" />
        <axis xyz="0 0 1" />
        <limit effort="28.0" lower="-6.283185307179586" upper="6.283185307179586" velocity="3.141592653589793" />
        <dynamics damping="0" friction="0" />
    </joint>
    <joint name="ur5e_wrist_2_joint" type="revolute">
        <parent link="ur5e_wrist_1_link" />
        <child link="ur5e_wrist_2_link" />
        <origin rpy="1.570342111810757 0 1.704767151727719e-06" xyz="-8.983203783231124e-06 -0.09977533286561772 4.531945435176372e-05" />
        <axis xyz="0 0 1" />
        <limit effort="28.0" lower="-6.283185307179586" upper="6.283185307179586" velocity="3.141592653589793" />
        <dynamics damping="0" friction="0" />
    </joint>
    <joint name="ur5e_wrist_3_joint" type="revolute">
        <parent link="ur5e_wrist_2_link" />
        <child link="ur5e_wrist_3_link" />
        <origin rpy="1.571954277330837 3.141592653589793 3.141592012208409" xyz="7.953268938776715e-05 0.09953502149750347 0.0001152566830018228" />
        <axis xyz="0 0 1" />
        <limit effort="28.0" lower="-6.283185307179586" upper="6.283185307179586" velocity="3.141592653589793" />
        <dynamics damping="0" friction="0" />
    </joint>
    <!-- ROS-Industrial 'base' frame: base_link to UR 'Base' Coordinates transform -->
    <link name="ur5e_base" />
    <joint name="ur5e_base_link-base_fixed_joint" type="fixed">
        <!-- Note the rotation over Z of pi radians: as base_link is REP-103
           aligned (ie: has X+ forward, Y+ left and Z+ up), this is needed
           to correctly align 'base' with the 'Base' coordinate system of
           the UR controller.
      -->
        <origin rpy="0 0 3.141592653589793" xyz="0 0 0" />
        <parent link="ur5e_base_link" />
        <child link="ur5e_base" />
    </joint>
    <!-- ROS-Industrial 'flange' frame: attachment point for EEF models -->
    <link name="ur5e_flange" />
    <joint name="ur5e_wrist_3-flange" type="fixed">
        <parent link="ur5e_wrist_3_link" />
        <child link="ur5e_flange" />
        <origin rpy="0 -1.5707963267948966 -1.5707963267948966" xyz="0 0 0" />
    </joint>
    <!-- ROS-Industrial 'tool0' frame: all-zeros tool frame -->
    <link name="ur5e_tool0" />
    <joint name="ur5e_flange-tool0" type="fixed">
        <!-- default toolframe: X+ left, Y+ up, Z+ front -->
        <origin rpy="1.5707963267948966 0 1.5707963267948966" xyz="0 0 0" />
        <parent link="ur5e_flange" />
        <child link="ur5e_tool0" />
    </joint>
    <link name="2f85_robotiq_arg2f_base_link">
        <inertial>
            <origin rpy="0 0 0" xyz="8.625E-08 -4.6583E-06 0.03145" />
            <mass value="0.22652" />
            <inertia ixx="0.00020005" ixy="-4.2442E-10" ixz="-2.9069E-10" iyy="0.00017832" iyz="-3.4402E-08" izz="0.00013478" />
        </inertial>
        <visual>
            <origin rpy="0 0 0" xyz="0 0 0" />
            <geometry>
                <mesh filename="package://robotiq_2f_85_gripper_visualization/meshes/visual/robotiq_arg2f_85_base_link.dae" scale="0.001 0.001 0.001" />
            </geometry>
            <material name="">
                <color rgba="0.1 0.1 0.1 1" />
            </material>
        </visual>
        <collision>
            <origin rpy="0 0 0" xyz="0 0 0" />
            <geometry>
                <mesh filename="package://robotiq_2f_85_gripper_visualization/meshes/collision/robotiq_arg2f_base_link.stl" />
            </geometry>
        </collision>
    </link>
    <link name="2f85_left_outer_knuckle">
        <!--<inertial>
        <origin xyz="-0.000200000000003065 0.0199435877845359 0.0292245259211331" rpy="0 0 0" />
        <mass value="0.00853198276973456" />
        <inertia ixx="2.89328108496468E-06" ixy="-1.57935047237397E-19" ixz="-1.93980378593255E-19" iyy="1.86719750325683E-06" iyz="-1.21858577871576E-06" izz="1.21905238907251E-06" />
        </inertial> -->
        <visual>
            <origin rpy="0 0 0" xyz="0 0 0" />
            <geometry>
                <mesh filename="package://robotiq_2f_85_gripper_visualization/meshes/visual/robotiq_arg2f_85_outer_knuckle.dae" scale="0.001 0.001 0.001" />
            </geometry>
            <material name="">
                <color rgba="0.792156862745098 0.819607843137255 0.933333333333333 1" />
            </material>
        </visual>
        <collision>
            <origin rpy="0 0 0" xyz="0 0 0" />
            <geometry>
                <mesh filename="package://robotiq_2f_85_gripper_visualization/meshes/collision/robotiq_arg2f_85_outer_knuckle.dae" scale="0.001 0.001 0.001" />
            </geometry>
        </collision>
        <inertial>
            <mass value="0.1" />
            <origin xyz="0 0 0" rpy="0 0 0" />
            <inertia ixx="0.03" iyy="0.03" izz="0.03" ixy="0.0" ixz="0.0" iyz="0.0" />
        </inertial>
    </link>
    <link name="2f85_left_outer_finger">
        <!--<inertial>
        <origin xyz="0.00030115855001899 0.0373907951953854 -0.0208027427000385" rpy="0 0 0" />
        <mass value="0.022614240507152" />
        <inertia ixx="1.52518312458174E-05" ixy="9.76583423954399E-10" ixz="-5.43838577022588E-10" iyy="6.17694243867776E-06" iyz="6.78636130740228E-06" izz="1.16494917907219E-05" />
        </inertial> -->
        <visual>
            <origin rpy="0 0 0" xyz="0 0 0" />
            <geometry>
                <mesh filename="package://robotiq_2f_85_gripper_visualization/meshes/visual/robotiq_arg2f_85_outer_finger.dae" scale="0.001 0.001 0.001" />
            </geometry>
            <material name="">
                <color rgba="0.1 0.1 0.1 1" />
            </material>
        </visual>
        <collision>
            <origin rpy="0 0 0" xyz="0 0 0" />
            <geometry>
                <mesh filename="package://robotiq_2f_85_gripper_visualization/meshes/collision/robotiq_arg2f_85_outer_finger.dae" scale="0.001 0.001 0.001" />
            </geometry>
        </collision>
        <inertial>
            <mass value="0.1" />
            <origin xyz="0 0 0" rpy="0 0 0" />
            <inertia ixx="0.03" iyy="0.03" izz="0.03" ixy="0.0" ixz="0.0" iyz="0.0" />
        </inertial>
    </link>
    <link name="2f85_left_inner_finger">
        <!--<inertial>
        <origin xyz="0.000299999999999317 0.0160078233491243 -0.0136945669206257" rpy="0 0 0" />
        <mass value="0.0104003125914103" />
        <inertia ixx="2.71909453810972E-06" ixy="1.35402465472579E-21" ixz="-7.1817349065269E-22" iyy="7.69100314106116E-07" iyz="6.74715432769696E-07" izz="2.30315190420171E-06" />
        </inertial> -->
        <visual>
            <origin rpy="0 0 0" xyz="0 0 0" />
            <geometry>
                <mesh filename="package://robotiq_2f_85_gripper_visualization/meshes/visual/robotiq_arg2f_85_inner_finger.dae" scale="0.001 0.001 0.001" />
            </geometry>
            <material name="">
                <color rgba="0.1 0.1 0.1 1" />
            </material>
        </visual>
        <collision>
            <origin rpy="0 0 0" xyz="0 0 0" />
            <geometry>
                <mesh filename="package://robotiq_2f_85_gripper_visualization/meshes/collision/robotiq_arg2f_85_inner_finger.dae" scale="0.001 0.001 0.001" />
            </geometry>
        </collision>
        <inertial>
            <mass value="0.1" />
            <origin xyz="0 0 0" rpy="0 0 0" />
            <inertia ixx="0.03" iyy="0.03" izz="0.03" ixy="0.0" ixz="0.0" iyz="0.0" />
        </inertial>
    </link>
    <link name="2f85_left_inner_finger_pad">
        <visual>
            <origin rpy="0 0 0" xyz="0 0 0" />
            <geometry>
                <box size="0.022 0.00635 0.0375" />
            </geometry>
            <material name="">
                <color rgba="0.9 0.9 0.9 1" />
            </material>
        </visual>
        <collision>
            <origin rpy="0 0 0" xyz="0 0 0" />
            <geometry>
                <box size="0.022 0.00635 0.0375" />
            </geometry>
            <material name="">
                <color rgba="0.9 0.0 0.0 1" />
            </material>
        </collision>
        <inertial>
            <mass value="0.1" />
            <origin xyz="0 0 0" rpy="0 0 0" />
            <inertia ixx="0.03" iyy="0.03" izz="0.03" ixy="0.0" ixz="0.0" iyz="0.0" />
        </inertial>
    </link>
    <link name="2f85_left_inner_knuckle">
        <!--<inertial>
        <origin xyz="0.000123011831763771 0.0507850843201817 0.00103968640075166" rpy="0 0 0" />
       <mass value="0.0271177346495152" />
        <inertia ixx="2.61910379223783E-05" ixy="-2.43616858946494E-07" ixz="-6.37789906117123E-09" iyy="2.8270243746167E-06" iyz="-5.37200748039765E-07" izz="2.83695868220296E-05" />
        </inertial> -->
        <visual>
            <origin rpy="0 0 0" xyz="0 0 0" />
            <geometry>
                <mesh filename="package://robotiq_2f_85_gripper_visualization/meshes/visual/robotiq_arg2f_85_inner_knuckle.dae" scale="0.001 0.001 0.001" />
            </geometry>
            <material name="">
                <color rgba="0.1 0.1 0.1 1" />
            </material>
        </visual>
        <collision>
            <origin rpy="0 0 0" xyz="0 0 0" />
            <geometry>
                <mesh filename="package://robotiq_2f_85_gripper_visualization/meshes/collision/robotiq_arg2f_85_inner_knuckle.dae" scale="0.001 0.001 0.001" />
            </geometry>
        </collision>
        <inertial>
            <mass value="0.1" />
            <origin xyz="0 0 0" rpy="0 0 0" />
            <inertia ixx="0.03" iyy="0.03" izz="0.03" ixy="0.0" ixz="0.0" iyz="0.0" />
        </inertial>
    </link>
    <link name="2f85_right_outer_knuckle">
        <!--<inertial>
        <origin xyz="-0.000200000000003065 0.0199435877845359 0.0292245259211331" rpy="0 0 0" />
        <mass value="0.00853198276973456" />
        <inertia ixx="2.89328108496468E-06" ixy="-1.57935047237397E-19" ixz="-1.93980378593255E-19" iyy="1.86719750325683E-06" iyz="-1.21858577871576E-06" izz="1.21905238907251E-06" />
        </inertial> -->
        <visual>
            <origin rpy="0 0 0" xyz="0 0 0" />
            <geometry>
                <mesh filename="package://robotiq_2f_85_gripper_visualization/meshes/visual/robotiq_arg2f_85_outer_knuckle.dae" scale="0.001 0.001 0.001" />
            </geometry>
            <material name="">
                <color rgba="0.792156862745098 0.819607843137255 0.933333333333333 1" />
            </material>
        </visual>
        <collision>
            <origin rpy="0 0 0" xyz="0 0 0" />
            <geometry>
                <mesh filename="package://robotiq_2f_85_gripper_visualization/meshes/collision/robotiq_arg2f_85_outer_knuckle.dae" scale="0.001 0.001 0.001" />
            </geometry>
        </collision>
        <inertial>
            <mass value="0.1" />
            <origin xyz="0 0 0" rpy="0 0 0" />
            <inertia ixx="0.03" iyy="0.03" izz="0.03" ixy="0.0" ixz="0.0" iyz="0.0" />
        </inertial>
    </link>
    <link name="2f85_right_outer_finger">
        <!--<inertial>
        <origin xyz="0.00030115855001899 0.0373907951953854 -0.0208027427000385" rpy="0 0 0" />
        <mass value="0.022614240507152" />
        <inertia ixx="1.52518312458174E-05" ixy="9.76583423954399E-10" ixz="-5.43838577022588E-10" iyy="6.17694243867776E-06" iyz="6.78636130740228E-06" izz="1.16494917907219E-05" />
        </inertial> -->
        <visual>
            <origin rpy="0 0 0" xyz="0 0 0" />
            <geometry>
                <mesh filename="package://robotiq_2f_85_gripper_visualization/meshes/visual/robotiq_arg2f_85_outer_finger.dae" scale="0.001 0.001 0.001" />
            </geometry>
            <material name="">
                <color rgba="0.1 0.1 0.1 1" />
            </material>
        </visual>
        <collision>
            <origin rpy="0 0 0" xyz="0 0 0" />
            <geometry>
                <mesh filename="package://robotiq_2f_85_gripper_visualization/meshes/collision/robotiq_arg2f_85_outer_finger.dae" scale="0.001 0.001 0.001" />
            </geometry>
        </collision>
        <inertial>
            <mass value="0.1" />
            <origin xyz="0 0 0" rpy="0 0 0" />
            <inertia ixx="0.03" iyy="0.03" izz="0.03" ixy="0.0" ixz="0.0" iyz="0.0" />
        </inertial>
    </link>
    <link name="2f85_right_inner_finger">
        <!--<inertial>
        <origin xyz="0.000299999999999317 0.0160078233491243 -0.0136945669206257" rpy="0 0 0" />
        <mass value="0.0104003125914103" />
        <inertia ixx="2.71909453810972E-06" ixy="1.35402465472579E-21" ixz="-7.1817349065269E-22" iyy="7.69100314106116E-07" iyz="6.74715432769696E-07" izz="2.30315190420171E-06" />
        </inertial> -->
        <visual>
            <origin rpy="0 0 0" xyz="0 0 0" />
            <geometry>
                <mesh filename="package://robotiq_2f_85_gripper_visualization/meshes/visual/robotiq_arg2f_85_inner_finger.dae" scale="0.001 0.001 0.001" />
            </geometry>
            <material name="">
                <color rgba="0.1 0.1 0.1 1" />
            </material>
        </visual>
        <collision>
            <origin rpy="0 0 0" xyz="0 0 0" />
            <geometry>
                <mesh filename="package://robotiq_2f_85_gripper_visualization/meshes/collision/robotiq_arg2f_85_inner_finger.dae" scale="0.001 0.001 0.001" />
            </geometry>
        </collision>
        <inertial>
            <mass value="0.1" />
            <origin xyz="0 0 0" rpy="0 0 0" />
            <inertia ixx="0.03" iyy="0.03" izz="0.03" ixy="0.0" ixz="0.0" iyz="0.0" />
        </inertial>
    </link>
    <link name="2f85_right_inner_finger_pad">
        <visual>
            <origin rpy="0 0 0" xyz="0 0 0" />
            <geometry>
                <box size="0.022 0.00635 0.0375" />
            </geometry>
            <material name="">
                <color rgba="0.9 0.9 0.9 1" />
            </material>
        </visual>
        <collision>
            <origin rpy="0 0 0" xyz="0 0 0" />
            <geometry>
                <box size="0.022 0.00635 0.0375" />
            </geometry>
            <material name="">
                <color rgba="0.9 0.0 0.0 1" />
            </material>
        </collision>
        <inertial>
            <mass value="0.1" />
            <origin xyz="0 0 0" rpy="0 0 0" />
            <inertia ixx="0.03" iyy="0.03" izz="0.03" ixy="0.0" ixz="0.0" iyz="0.0" />
        </inertial>
    </link>
    <link name="2f85_right_inner_knuckle">
        <!--<inertial>
        <origin xyz="0.000123011831763771 0.0507850843201817 0.00103968640075166" rpy="0 0 0" />
       <mass value="0.0271177346495152" />
        <inertia ixx="2.61910379223783E-05" ixy="-2.43616858946494E-07" ixz="-6.37789906117123E-09" iyy="2.8270243746167E-06" iyz="-5.37200748039765E-07" izz="2.83695868220296E-05" />
        </inertial> -->
        <visual>
            <origin rpy="0 0 0" xyz="0 0 0" />
            <geometry>
                <mesh filename="package://robotiq_2f_85_gripper_visualization/meshes/visual/robotiq_arg2f_85_inner_knuckle.dae" scale="0.001 0.001 0.001" />
            </geometry>
            <material name="">
                <color rgba="0.1 0.1 0.1 1" />
            </material>
        </visual>
        <collision>
            <origin rpy="0 0 0" xyz="0 0 0" />
            <geometry>
                <mesh filename="package://robotiq_2f_85_gripper_visualization/meshes/collision/robotiq_arg2f_85_inner_knuckle.dae" scale="0.001 0.001 0.001" />
            </geometry>
        </collision>
        <inertial>
            <mass value="0.1" />
            <origin xyz="0 0 0" rpy="0 0 0" />
            <inertia ixx="0.03" iyy="0.03" izz="0.03" ixy="0.0" ixz="0.0" iyz="0.0" />
        </inertial>
    </link>
    <joint name="2f85_finger_joint" type="revolute">
        <origin rpy="0 0 3.141592653589793" xyz="0 -0.0306011 0.054904" />
        <parent link="2f85_robotiq_arg2f_base_link" />
        <child link="2f85_left_outer_knuckle" />
        <axis xyz="1 0 0" />
        <limit effort="1000" lower="0" upper="0.755" velocity="0.7" />
    </joint>
    <joint name="2f85_left_outer_finger_joint" type="fixed">
        <origin rpy="0 0 0" xyz="0 0.0315 -0.0041" />
        <parent link="2f85_left_outer_knuckle" />
        <child link="2f85_left_outer_finger" />
        <axis xyz="1 0 0" />
    </joint>
    <joint name="2f85_left_inner_knuckle_joint" type="revolute">
        <!-- <origin xyz="0 ${reflect * -0.0127} 0.06142" rpy="${pi / 2 + .725} 0 ${(reflect - 1) * pi / 2}" /> -->
        <origin rpy="0 0 3.141592653589793" xyz="0 -0.0127 0.06142" />
        <parent link="2f85_robotiq_arg2f_base_link" />
        <child link="2f85_left_inner_knuckle" />
        <axis xyz="1 0 0" />
        <limit effort="1000" lower="0" upper="0.8757" velocity="2.0" />
        <mimic joint="2f85_finger_joint" multiplier="1" offset="0" />
    </joint>
    <joint name="2f85_left_inner_finger_joint" type="revolute">
        <origin rpy="0 0 0" xyz="0 0.0061 0.0471" />
        <parent link="2f85_left_outer_finger" />
        <child link="2f85_left_inner_finger" />
        <axis xyz="1 0 0" />
        <limit effort="1000" lower="0" upper="0.8757" velocity="2.0" />
        <mimic joint="2f85_finger_joint" multiplier="-1" offset="0" />
    </joint>
    <joint name="2f85_left_inner_finger_pad_joint" type="fixed">
        <origin rpy="0 0 0" xyz="0 -0.0220203446692936 0.03242" />
        <parent link="2f85_left_inner_finger" />
        <child link="2f85_left_inner_finger_pad" />
        <axis xyz="0 0 1" />
    </joint>
    <joint name="2f85_right_outer_knuckle_joint" type="revolute">
        <origin rpy="0 0 0" xyz="0 0.0306011 0.054904" />
        <parent link="2f85_robotiq_arg2f_base_link" />
        <child link="2f85_right_outer_knuckle" />
        <axis xyz="1 0 0" />
        <limit effort="1000" lower="0" upper="0.81" velocity="2.0" />
        <mimic joint="2f85_finger_joint" multiplier="1" offset="0" />
    </joint>
    <joint name="2f85_right_outer_finger_joint" type="fixed">
        <origin rpy="0 0 0" xyz="0 0.0315 -0.0041" />
        <parent link="2f85_right_outer_knuckle" />
        <child link="2f85_right_outer_finger" />
        <axis xyz="1 0 0" />
    </joint>
    <joint name="2f85_right_inner_knuckle_joint" type="revolute">
        <!-- <origin xyz="0 ${reflect * -0.0127} 0.06142" rpy="${pi / 2 + .725} 0 ${(reflect - 1) * pi / 2}" /> -->
        <origin rpy="0 0 0.0" xyz="0 0.0127 0.06142" />
        <parent link="2f85_robotiq_arg2f_base_link" />
        <child link="2f85_right_inner_knuckle" />
        <axis xyz="1 0 0" />
        <limit effort="1000" lower="0" upper="0.8757" velocity="2.0" />
        <mimic joint="2f85_finger_joint" multiplier="1" offset="0" />
    </joint>
    <joint name="2f85_right_inner_finger_joint" type="revolute">
        <origin rpy="0 0 0" xyz="0 0.0061 0.0471" />
        <parent link="2f85_right_outer_finger" />
        <child link="2f85_right_inner_finger" />
        <axis xyz="1 0 0" />
        <limit effort="1000" lower="0" upper="0.8757" velocity="2.0" />
        <mimic joint="2f85_finger_joint" multiplier="-1" offset="0" />
    </joint>
    <joint name="2f85_right_inner_finger_pad_joint" type="fixed">
        <origin rpy="0 0 0" xyz="0 -0.0220203446692936 0.03242" />
        <parent link="2f85_right_inner_finger" />
        <child link="2f85_right_inner_finger_pad" />
        <axis xyz="0 0 1" />
    </joint>
    <transmission name="2f85_finger_joint_trans">
        <type>transmission_interface/SimpleTransmission</type>
        <joint name="2f85_finger_joint">
            <hardwareInterface>PositionJointInterface</hardwareInterface>
        </joint>
        <actuator name="2f85_finger_joint_motor">
            <mechanicalReduction>1</mechanicalReduction>
            <hardwareInterface>hardware_interface/EffortJointInterface</hardwareInterface>
        </actuator>
    </transmission>
    <!-- Tool Center Point: Center of the fingertips when gripper is closed -->
    <joint name="2f85_tcp_joint" type="fixed">
        <origin rpy="0 -1.5707963267948966 0" xyz="0 0 0.14" />
        <parent link="2f85_robotiq_arg2f_base_link" />
        <child link="2f85_tcp" />
    </joint>
    <link name="2f85_tcp" />
    <!-- add gripper to robot -->
    <joint name="ur5e_robotiq_arg2f_base_joint" type="fixed">
        <origin rpy="0 0 -1.5707963267948966" xyz="0 0 0" />
        <parent link="ur5e_tool0" />
        <child link="2f85_robotiq_arg2f_base_link" />
    </joint>
    <!-- link robot to enclosure -->
    <joint name="enclosure_to_ur5e" type="fixed">
        <parent link="enclosure" />
        <child link="ur5e_base_link" />
        <origin rpy="0 0 3.141592653589793" xyz="-0.0775 0 0.42" />
    </joint>
    <transmission name="trans_mir100_fl_caster_rotation_joint">
        <type>transmission_interface/SimpleTransmission</type>
        <joint name="mir100_fl_caster_rotation_joint">
            <hardwareInterface>hardware_interface/EffortJointInterface</hardwareInterface>
        </joint>
        <actuator name="mir100_fl_caster_rotation_joint_motor">
            <hardwareInterface>hardware_interface/EffortJointInterface</hardwareInterface>
            <mechanicalReduction>1</mechanicalReduction>
        </actuator>
    </transmission>
    <transmission name="trans_mir100_fl_caster_wheel_joint">
        <type>transmission_interface/SimpleTransmission</type>
        <joint name="mir100_fl_caster_wheel_joint">
            <hardwareInterface>hardware_interface/EffortJointInterface</hardwareInterface>
        </joint>
        <actuator name="mir100_fl_caster_wheel_joint_motor">
            <hardwareInterface>hardware_interface/EffortJointInterface</hardwareInterface>
            <mechanicalReduction>1</mechanicalReduction>
        </actuator>
    </transmission>
    <transmission name="trans_mir100_fr_caster_rotation_joint">
        <type>transmission_interface/SimpleTransmission</type>
        <joint name="mir100_fr_caster_rotation_joint">
            <hardwareInterface>hardware_interface/EffortJointInterface</hardwareInterface>
        </joint>
        <actuator name="mir100_fr_caster_rotation_joint_motor">
            <hardwareInterface>hardware_interface/EffortJointInterface</hardwareInterface>
            <mechanicalReduction>1</mechanicalReduction>
        </actuator>
    </transmission>
    <transmission name="trans_mir100_fr_caster_wheel_joint">
        <type>transmission_interface/SimpleTransmission</type>
        <joint name="mir100_fr_caster_wheel_joint">
            <hardwareInterface>hardware_interface/EffortJointInterface</hardwareInterface>
        </joint>
        <actuator name="mir100_fr_caster_wheel_joint_motor">
            <hardwareInterface>hardware_interface/EffortJointInterface</hardwareInterface>
            <mechanicalReduction>1</mechanicalReduction>
        </actuator>
    </transmission>
    <transmission name="trans_mir100_bl_caster_rotation_joint">
        <type>transmission_interface/SimpleTransmission</type>
        <joint name="mir100_bl_caster_rotation_joint">
            <hardwareInterface>hardware_interface/EffortJointInterface</hardwareInterface>
        </joint>
        <actuator name="mir100_bl_caster_rotation_joint_motor">
            <hardwareInterface>hardware_interface/EffortJointInterface</hardwareInterface>
            <mechanicalReduction>1</mechanicalReduction>
        </actuator>
    </transmission>
    <transmission name="trans_mir100_bl_caster_wheel_joint">
        <type>transmission_interface/SimpleTransmission</type>
        <joint name="mir100_bl_caster_wheel_joint">
            <hardwareInterface>hardware_interface/EffortJointInterface</hardwareInterface>
        </joint>
        <actuator name="mir100_bl_caster_wheel_joint_motor">
            <hardwareInterface>hardware_interface/EffortJointInterface</hardwareInterface>
            <mechanicalReduction>1</mechanicalReduction>
        </actuator>
    </transmission>
    <transmission name="trans_mir100_br_caster_rotation_joint">
        <type>transmission_interface/SimpleTransmission</type>
        <joint name="mir100_br_caster_rotation_joint">
            <hardwareInterface>hardware_interface/EffortJointInterface</hardwareInterface>
        </joint>
        <actuator name="mir100_br_caster_rotation_joint_motor">
            <hardwareInterface>hardware_interface/EffortJointInterface</hardwareInterface>
            <mechanicalReduction>1</mechanicalReduction>
        </actuator>
    </transmission>
    <transmission name="trans_mir100_br_caster_wheel_joint">
        <type>transmission_interface/SimpleTransmission</type>
        <joint name="mir100_br_caster_wheel_joint">
            <hardwareInterface>hardware_interface/EffortJointInterface</hardwareInterface>
        </joint>
        <actuator name="mir100_br_caster_wheel_joint_motor">
            <hardwareInterface>hardware_interface/EffortJointInterface</hardwareInterface>
            <mechanicalReduction>1</mechanicalReduction>
        </actuator>
    </transmission>
    <transmission name="trans_2f85_left_inner_knuckle_joint">
        <type>transmission_interface/SimpleTransmission</type>
        <joint name="2f85_left_inner_knuckle_joint">
            <hardwareInterface>hardware_interface/EffortJointInterface</hardwareInterface>
        </joint>
        <actuator name="2f85_left_inner_knuckle_joint_motor">
            <hardwareInterface>hardware_interface/EffortJointInterface</hardwareInterface>
            <mechanicalReduction>1</mechanicalReduction>
        </actuator>
    </transmission>
    <transmission name="trans_2f85_left_inner_finger_joint">
        <type>transmission_interface/SimpleTransmission</type>
        <joint name="2f85_left_inner_finger_joint">
            <hardwareInterface>hardware_interface/EffortJointInterface</hardwareInterface>
        </joint>
        <actuator name="2f85_left_inner_finger_joint_motor">
            <hardwareInterface>hardware_interface/EffortJointInterface</hardwareInterface>
            <mechanicalReduction>1</mechanicalReduction>
        </actuator>
    </transmission>
    <transmission name="trans_2f85_right_outer_knuckle_joint">
        <type>transmission_interface/SimpleTransmission</type>
        <joint name="2f85_right_outer_knuckle_joint">
            <hardwareInterface>hardware_interface/EffortJointInterface</hardwareInterface>
        </joint>
        <actuator name="2f85_right_outer_knuckle_joint_motor">
            <hardwareInterface>hardware_interface/EffortJointInterface</hardwareInterface>
            <mechanicalReduction>1</mechanicalReduction>
        </actuator>
    </transmission>
    <transmission name="trans_2f85_right_inner_knuckle_joint">
        <type>transmission_interface/SimpleTransmission</type>
        <joint name="2f85_right_inner_knuckle_joint">
            <hardwareInterface>hardware_interface/EffortJointInterface</hardwareInterface>
        </joint>
        <actuator name="2f85_right_inner_knuckle_joint_motor">
            <hardwareInterface>hardware_interface/EffortJointInterface</hardwareInterface>
            <mechanicalReduction>1</mechanicalReduction>
        </actuator>
    </transmission>
    <transmission name="trans_2f85_right_inner_finger_joint">
        <type>transmission_interface/SimpleTransmission</type>
        <joint name="2f85_right_inner_finger_joint">
            <hardwareInterface>hardware_interface/EffortJointInterface</hardwareInterface>
        </joint>
        <actuator name="2f85_right_inner_finger_joint_motor">
            <hardwareInterface>hardware_interface/EffortJointInterface</hardwareInterface>
            <mechanicalReduction>1</mechanicalReduction>
        </actuator>
    </transmission>
</robot>
